<mujocoinclude>

    <compiler angle="radian" inertiafromgeom="auto" inertiagrouprange="4 5"/>
    <asset>
      <texture name="T_hmr_met" type="cube" file="../objects/textures/metal1.png"/>
      <texture name="T_hmr_wood" type="cube" file="../objects/textures/wood1.png"/>

      <material name="hmr_col" rgba="0.3 0.3 1.0 0.5" shininess="0" specular="0"/>
      <material name="hmr_red" rgba=".65 0 0 1" shininess="1" reflectance=".7" specular=".5"/>
      <material name="hmr_metal" texture="T_hmr_met" rgba=".65 .65 .65 1" shininess="1" reflectance=".7" specular=".5"/>
      <material name="hmr_wood" texture="T_hmr_wood" shininess="1" reflectance=".7" specular=".5"/>

    </asset>
    <asset>
        <mesh file="../../../objects/meshes/hammer/hammerblock.stl" name="hammerblock"/>
        <mesh file="../../../objects/meshes/hammer/nail.stl" name="nail"/>
        <mesh file="../../../objects/meshes/hammer/hammerhandle.stl" name="hammerhandle"/>

    </asset>
    <default>

      <default class="hmr_base">
          <joint armature="0.001" damping="2" limited="true"/>
          <geom conaffinity="0" contype="0" group="1" type="mesh"/>
          <position ctrllimited="true" ctrlrange="0 1.57"/>
          <default class="hmr_viz">
              <geom condim="4" type="mesh"/>
          </default>
          <default class="hmr_col">
              <geom conaffinity="1" condim="3" contype="1" group="4" material="hmr_col" solimp="0.99 0.99 0.01" solref="0.01 1"/>
          </default>
      </default>
    </default>
    
    <worldbody>
    
      <body pos="0.5 0.5 0.05">
          <freejoint/>
          <body childclass="hmr_base" name="hammer">
              <geom material="hmr_red" euler="0 1.57 0" size="0.02 0.14" type="capsule" name="HammerHandle"/>
              <geom material="hmr_metal" euler="0 1.57 0" pos="0.16 0 0" size="0.026 0.025" type="cylinder"/>
              <geom material="hmr_metal" euler="1.57 0 0" pos="0.16 0.026 0" size="0.02 0.015" type="cylinder"/>
              <geom material="hmr_metal" euler="1.57 0 0" pos="0.16 0.056 0" size="0.038 0.016" type="cylinder"/>
              <geom material="hmr_metal" euler="1.57 0 0" pos="0.16 -0.056 0" size="0.038 0.016" type="cylinder"/>
              <geom material="hmr_metal" euler="1.57 0 0" pos="0.16 -0.026 0" size="0.02 0.015" type="cylinder"/>

              <geom class="hmr_col" euler="0 1.57 0" size="0.02 0.14" type="capsule" mass=".01"/>
              <geom class="hmr_col" euler="0 1.57 0" pos="0.16 0 0.0" size="0.026 0.025" type="cylinder" mass=".02"/>
              <geom class="hmr_col" euler="1.57 0 0" pos="0.16 0.026 0" size="0.02 0.015" type="cylinder" mass=".01"/>
              <geom class="hmr_col" euler="1.57 0 0" pos="0.16 0.056 0" size="0.038 0.016" type="cylinder" mass=".03"/>
              <geom class="hmr_col" euler="1.57 0 0" pos="0.16 -0.056 0.0" size="0.038 0.016" type="cylinder" mass=".03"/>
              <geom class="hmr_col" euler="1.57 0 0" pos="0.16 -0.026 0.0" size="0.02 0.015" type="cylinder" mass=".01"/>
          </body>
      </body>
    
    </worldbody>
    
    <worldbody>
	<body childclass="hmr_base" name="hammerblock" pos="0.5 -0.6 -0.015" euler="0 0 3.1416">
	    
	    <geom material="hmr_wood" mesh="hammerblock" pos="0 0 0.11"/>
	    <geom class="hmr_col" pos="0 0 0.172" size="0.1 0.1 0.048" type="box"/>
	    <geom class="hmr_col" pos="0.058 0 0.11" size="0.042 0.1 0.014" type="box"/>
	    <geom class="hmr_col" pos="-0.058 0 0.11" size="0.042 0.1 0.014" type="box"/>
	    <geom class="hmr_col" pos="0 0 0.048" size="0.1 0.1 0.048" type="box"/>
	    <body name="nail_link" pos="0 -0.21 0.11">
		<joint type="slide" axis="0 1 0" range="0 .1" name="NailSlideJoint"/>
		<geom material="hmr_metal" euler="1.57 0 0" mesh="nail" pos="-0.0 0.057 0"/>
		<geom class="hmr_col" euler="1.57 0 0" pos="0.0 0.057 0" size="0.01 0.06" type="cylinder"/>
		<geom class="hmr_col" euler="1.57 0 0" size="0.03 0.009" type="cylinder"/>
	    </body>
	</body>
    </worldbody>

</mujocoinclude>

